Workbook

Sheet Data
A1: Data | B1: Ultimo | C1: Apertura | D1: Massimo | E1: Minimo | F1: Vol. | G1: Var. % | J1: Data | K1: Ultimo | L1: Apertura | M1: Massimo | N1: Minimo | O1: Vol. | P1: Var. % | S1: S&P 500 | T1: Data | U1: Ultimo | V1: Apertura | W1: Massimo | X1: Minimo | Y1: Vol. | Z1: Var. %
A2: 42006 | B2: 23.57 | C2: 23.7 | D2: 23.89 | E2: 23.24 | F2: 395,71K | G2: -0.0004 | J2: 42008 | K2: 23.87 | L2: 23.39 | M2: 23.95 | N2: 21.98 | O2: 5,17M | P2: 0.0127 | T2: 42008 | U2: 2044.8 | V2: 2054.4 | W2: 2064.4 | X2: 1992.4 | Z2: -0.0065
A3: 42009 | B3: 22.85 | C3: 23.39 | D3: 23.46 | E3: 22.54 | F3: 982,71K | G3: -0.0305 | J3: 42015 | K3: 23.95 | L3: 23.85 | M3: 24.35 | N3: 23.11 | O3: 6,36M | P3: 0.0034 | T3: 42015 | U3: 2019.4 | V3: 2046.1 | W3: 2056.9 | X3: 1988.1 | Z3: -0.0124
A4: 42010 | B4: 22.13 | C4: 22.51 | D4: 22.81 | E4: 21.98 | F4: 1,20M | G4: -0.0315 | J4: 42022 | K4: 24.62 | L4: 24.03 | M4: 25.17 | N4: 23.48 | O4: 3,72M | P4: 0.028 | T4: 42022 | U4: 2051.8 | V4: 2020.8 | W4: 2064.6 | X4: 2004.5 | Z4: 0.016
A5: 42011 | B5: 22.78 | C5: 22.3 | D5: 23.09 | E5: 22.22 | F5: 1,05M | G5: 0.0294 | J5: 42029 | K5: 24.87 | L5: 24.62 | M5: 25.58 | N5: 24.52 | O5: 5,29M | P5: 0.0102 | T5: 42029 | U5: 1995 | V5: 2050.4 | W5: 2057.6 | X5: 1989.2 | Z5: -0.0277
A6: 42012 | B6: 23.82 | C6: 23.01 | D6: 23.83 | E6: 22.79 | F6: 890,73K | G6: 0.0457 | J6: 42036 | K6: 24.3 | L6: 24.9 | M6: 25.8 | N6: 23.72 | O6: 7,00M | P6: -0.0229 | T6: 42036 | U6: 2055.5 | V6: 1996.7 | W6: 2072.4 | X6: 1980.9 | Z6: 0.0303
A7: 42013 | B7: 23.87 | C7: 23.8 | D7: 23.95 | E7: 23.66 | F7: 1,04M | G7: 0.0021 | J7: 42043 | K7: 23.7 | L7: 24.29 | M7: 24.4 | N7: 23.04 | O7: 9,02M | P7: -0.0247 | T7: 42043 | U7: 2097 | V7: 2053.5 | W7: 2097 | X7: 2041.9 | Z7: 0.0202
A8: 42016 | B8: 23.44 | C8: 23.85 | D8: 23.85 | E8: 23.35 | F8: 1,10M | G8: -0.018 | J8: 42050 | K8: 23.5 | L8: 23.78 | M8: 23.9 | N8: 23.03 | O8: 3,97M | P8: -0.0084 | T8: 42050 | U8: 2110.3 | V8: 2096.5 | W8: 2110.6 | X8: 2085.4 | Z8: 0.0063
A9: 42017 | B9: 23.96 | C9: 23.67 | D9: 24 | E9: 23.45 | F9: 2,11M | G9: 0.0222 | J9: 42057 | K9: 23.32 | L9: 23.43 | M9: 23.78 | N9: 22.85 | O9: 6,63M | P9: -0.0077 | T9: 42057 | U9: 2104.5 | V9: 2109.8 | W9: 2119.6 | X9: 2103 | Z9: -0.0027
A10: 42018 | B10: 24.1 | C10: 23.63 | D10: 24.26 | E10: 23.45 | F10: 1,22M | G10: 0.0058 | J10: 42064 | K10: 22.28 | L10: 23.38 | M10: 23.52 | N10: 22 | O10: 7,11M | P10: -0.0446 | T10: 42064 | U10: 2071.3 | V10: 2105.2 | W10: 2117.5 | X10: 2067.3 | Z10: -0.0158
A11: 42019 | B11: 23.52 | C11: 24.11 | D11: 24.35 | E11: 23.3 | F11: 1,06M | G11: -0.0241 | J11: 42071 | K11: 22.53 | L11: 22.32 | M11: 22.6 | N11: 21.49 | O11: 5,72M | P11: 0.0112 | T11: 42071 | U11: 2053.4 | V11: 2072.2 | W11: 2083.5 | X11: 2039.7 | Z11: -0.0086
A12: 42020 | B12: 23.95 | C12: 23.55 | D12: 24.05 | E12: 23.11 | F12: 865,65K | G12: 0.0183 | J12: 42078 | K12: 22.24 | L12: 22.66 | M12: 22.77 | N12: 21.86 | O12: 4,24M | P12: -0.0129 | T12: 42078 | U12: 2108.1 | V12: 2055.3 | W12: 2113.9 | X12: 2055.3 | Z12: 0.0266
A13: 42024 | B13: 23.92 | C13: 24.03 | D13: 24.08 | E13: 23.48 | F13: 656,46K | G13: -0.0013 | J13: 42085 | K13: 21.07 | L13: 22.23 | M13: 22.43 | N13: 20.96 | O13: 6,86M | P13: -0.0526 | T13: 42085 | U13: 2061 | V13: 2108 | W13: 2114.9 | X13: 2045.5 | Z13: -0.0223
... A523: 42762 | B523: 21.18 | C523: 21.25 | D523: 21.31 | E523: 21.09 | F523: 1,79M | G523: -0.0231 | J523: 45655 | K523: 169.06 | L523: 167.95 | M523: 169.43 | N523: 163.05 | O523: 10,99M | P523: -0.0072 | T523: 45655 | U523: 5942.47 | V523: 5920.67 | W523: 5949.34 | X523: 5829.53 | Z523: -0.0048
A524: 42765 | B524: 21.03 | C524: 21.14 | D524: 21.14 | E524: 20.88 | F524: 849,15K | G524: -0.0071
A525: 42766 | B525: 21.24 | C525: 20.87 | D525: 21.45 | E525: 20.75 | F525: 811,12K | G525: 0.01
A526: 42767 | B526: 21.43 | C526: 21.29 | D526: 21.7 | E526: 21.02 | F526: 638,20K | G526: 0.0089
A527: 42768 | B527: 21.7 | C527: 21.48 | D527: 21.71 | E527: 21.21 | F527: 969,50K | G527: 0.0126
A528: 42769 | B528: 22.13 | C528: 22.32 | D528: 22.45 | E528: 21.81 | F528: 1,80M | G528: 0.0198
A529: 42772 | B529: 22.14 | C529: 22.33 | D529: 22.45 | E529: 22.14 | F529: 1,64M | G529: 0.0005
A530: 42773 | B530: 22.81 | C530: 22.35 | D530: 22.93 | E530: 22.21 | F530: 2,18M | G530: 0.0303
A531: 42774 | B531: 22.91 | C531: 22.91 | D531: 23.39 | E531: 22.6 | F531: 2,46M | G531: 0.0044
A532: 42775 | B532: 23.55 | C532: 23.43 | D532: 24 | E532: 23.2 | F532: 1,66M | G532: 0.0279
A533: 42776 | B533: 23.62 | C533: 23.8 | D533: 23.84 | E533: 23.34 | F533: 1,98M | G533: 0.003
A534: 42779 | B534: 23.34 | C534: 23.83 | D534: 23.93 | E534: 23.33 | F534: 1,24M | G534: -0.0119
A535: 42780 | B535: 23.34 | C535: 23.31 | D535: 23.47 | E535: 23.08 | F535: 919,49K | G535: 0
... A2517: 45657 | B2517: 165.16 | C2517: 167 | D2517: 167.6 | E2517: 164.93 | F2517: 2,82M | G2517: -0.0081

Sheet Statistics 1
B4: EQUITY | D4: Change % by day | G4: Time span | J4: Returns statistics | M4: Frequency table | U4: Normal distribution
B5: Date | C5: Price | D5: Var % | E5: Ln Var % | G5: Start date: | H5: 42005 | J5: Average price | K5: =AVERAGE(C6:C3709) -> 49.433474 | M5: Class | N5: Abs Freq | O5: Rel Freq | P5: Cum Freq | Q5: Cum Rel Freq | R5: Sum Data | U5: Abs | V5: Cum | AJ5: Date | AK5: 1 + var % | AM5: Avg var % 90d | AN5: Volat 90d | AQ5: Avg var % 90d | AR5: Volat 90d | AT5: Geometric mean | AW5: Quartile var %
B6: 42006 | C6: 23.57 | G6: Last date: | H6: 45657 | J6: Average Var % | K6: =AVERAGE(D7:D3709) -> 0.0010357652 | M6: =MIN(D7:D2521) -> -0.15901235 | N6: {=FREQUENCY($D$7:$D$3709,M6:M26)} -> 1 | O6: =N6/$K$16 -> 0.00039761431 | P6: =N6 -> 1 | Q6: =P6/$K$16 -> 0.00039761431 | U6: =_xlfn.NORM.DIST(M6,$K$6,$K$8,FALSE) -> 4.5386211e-10 | V6: =_xlfn.NORM.DIST(M6,$K$6,$K$8,TRUE) -> 1.4614981e-12 | AJ6: 42006 | AP6: Avg | AQ6: =AVERAGE(AM7:AM3709) -> 0.0010214753 | AR6: =AVERAGE(AN7:AN3709) -> 0.021249974 | AT6: =GEOMEAN(AL7:AL3709)-1 -> #NUM! | AW6: 1 | AX6: =QUARTILE(D7:D3709,AW6) -> -0.0099019379
B7: 42009 | C7: 22.85 | D7: =((C7-C6)/C6) -> -0.030547306 | E7: =IF(C7=C6, 0, LN(C7/C6)) -> -0.0310236 | J7: Median | K7: =MEDIAN(C6:C3709) -> 40.715 | M7: =M6+$K$8 -> -0.13608734 | N7: 0 | O7: =N7/$K$16 -> 0 | P7: =P6+N7 -> 1 | Q7: =P7/$K$16 -> 0.00039761431 | U7: =_xlfn.NORM.DIST(M7,$K$6,$K$8,FALSE) -> 2.9631281e-07 | V7: =_xlfn.NORM.DIST(M7,$K$6,$K$8,TRUE) -> 1.1062918e-09 | AJ7: 42009 | AK7: =1 + D7 -> 0.96945269 | AL7: =1 + E7 -> 0.9689764 | AM7: =AVERAGE(D7:D97) -> -0.00082143167 | AN7: =STDEV(D7:D97) -> 0.014707578 | AP7: Std dev | AQ7: =STDEV(AM7:AM3708) -> 0.0021004301 | AR7: =STDEV(AN7:AN3708) -> 0.0088252081 | AW7: 2 | AX7: =QUARTILE(D8:D3710,AW7) -> 0.0012895159
B8: 42010 | C8: 22.13 | D8: =((C8-C7)/C7) -> -0.031509847 | E8: =IF(C8=C7, 0, LN(C8/C7)) -> -0.032016963 | J8: Standard Deviation | K8: =_xlfn.STDEV.S(D7:D3709) -> 0.022925004 | M8: =M7+$K$8 -> -0.11316234 | N8: 2 | O8: =N8/$K$16 -> 0.00079522863 | P8: =P7+N8 -> 3 | Q8: =P8/$K$16 -> 0.0011928429 | U8: =_xlfn.NORM.DIST(M8,$K$6,$K$8,FALSE) -> 7.1167621e-05 | V8: =_xlfn.NORM.DIST(M8,$K$6,$K$8,TRUE) -> 3.1566614e-07 | AJ8: 42010 | AK8: =1 + D8 -> 0.96849015 | AL8: =1 + E8 -> 0.96798304 | AM8: =AVERAGE(D8:D98) -> -0.00037920533 | AN8: =STDEV(D8:D98) -> 0.01440576 | AP8: Max | AQ8: =MAX(AM7:AM3708) -> 0.0091809583 | AR8: =MAX(AN7:AN3708) -> 0.06260939 | AT8: Harmonic mean | AW8: 3 | AX8: =QUARTILE(D9:D3711,AW8) -> 0.012353706
B9: 42011 | C9: 22.78 | D9: =((C9-C8)/C8) -> 0.029371893 | E9: =IF(C9=C8, 0, LN(C9/C8)) -> 0.028948804 | J9: Kurtosis | K9: =KURT(D7:D3709) -> 12.587162 | M9: =M8+$K$8 -> -0.090237333 | N9: 5 | O9: =N9/$K$16 -> 0.0019880716 | P9: =P8+N9 -> 8 | Q9: =P9/$K$16 -> 0.0031809145 | U9: =_xlfn.NORM.DIST(M9,$K$6,$K$8,FALSE) -> 0.006288108 | V9: =_xlfn.NORM.DIST(M9,$K$6,$K$8,TRUE) -> 3.4258508e-05 | AJ9: 42011 | AK9: =1 + D9 -> 1.0293719 | AL9: =1 + E9 -> 1.0289488 | AM9: =AVERAGE(D9:D99) -> -0.00010831372 | AN9: =STDEV(D9:D99) -> 0.014041021 | AP9: Min | AQ9: =MIN(AM7:AM3708) -> -0.017901165 | AR9: =MIN(AN7:AN3708) -> 0.0085069386 | AT9: =HARMEAN(AK7:AK3709)-1 -> 0.00051341009 | AW9: 4 | AX9: =QUARTILE(D10:D3712,AW9) -> 0.26237263
B10: 42012 | C10: 23.82 | D10: =((C10-C9)/C9) -> 0.045654083 | E10: =IF(C10=C9, 0, LN(C10/C9)) -> 0.044642606 | J10: Skewness | K10: =_xlfn.SKEW.P(D7:D3709) -> 0.50435697 | M10: =M9+$K$8 -> -0.067312328 | N10: 10 | O10: =N10/$K$16 -> 0.0039761431 | P10: =P9+N10 -> 18 | Q10: =P10/$K$16 -> 0.0071570577 | U10: =_xlfn.NORM.DIST(M10,$K$6,$K$8,FALSE) -> 0.2043916 | V10: =_xlfn.NORM.DIST(M10,$K$6,$K$8,TRUE) -> 0.0014347739 | AJ10: 42012 | AK10: =1 + D10 -> 1.0456541 | AL10: =1 + E10 -> 1.0446426 | AM10: =AVERAGE(D10:D100) -> -0.00051203214 | AN10: =STDEV(D10:D100) -> 0.013708185
B11: 42013 | C11: 23.87 | D11: =((C11-C10)/C10) -> 0.0020990764 | E11: =IF(C11=C10, 0, LN(C11/C10)) -> 0.0020968764 | J11: Minimum | K11: =MIN(D7:D3709) -> -0.15901235 | M11: =M10+$K$8 -> -0.044387324 | N11: 40 | O11: =N11/$K$16 -> 0.015904573 | P11: =P10+N11 -> 58 | Q11: =P11/$K$16 -> 0.02306163 | U11: =_xlfn.NORM.DIST(M11,$K$6,$K$8,FALSE) -> 2.4440587 | V11: =_xlfn.NORM.DIST(M11,$K$6,$K$8,TRUE) -> 0.023774475 | AJ11: 42013 | AK11: =1 + D11 -> 1.0020991 | AL11: =1 + E11 -> 1.0020969 | AM11: =AVERAGE(D11:D101) -> -0.0008913987 | AN11: =STDEV(D11:D101) -> 0.012868333
B12: 42016 | C12: 23.44 | D12: =((C12-C11)/C11) -> -0.018014244 | E12: =IF(C12=C11, 0, LN(C12/C11)) -> -0.018178476 | J12: Maximum | K12: =MAX(D7:D3709) -> 0.26237263 | M12: =M11+$K$8 -> -0.021462319 | N12: 236 | O12: =N12/$K$16 -> 0.093836978 | P12: =P11+N12 -> 294 | Q12: =P12/$K$16 -> 0.11689861 | U12: =_xlfn.NORM.DIST(M12,$K$6,$K$8,FALSE) -> 10.751417 | V12: =_xlfn.NORM.DIST(M12,$K$6,$K$8,TRUE) -> 0.1632033 | AJ12: 42016 | AK12: =1 + D12 -> 0.98198576 | AL12: =1 + E12 -> 0.98182152 | AM12: =AVERAGE(D12:D102) -> -0.00097495544 | AN12: =STDEV(D12:D102) -> 0.012873385
B13: 42017 | C13: 23.96 | D13: =((C13-C12)/C12) -> 0.0221843 | E13: =IF(C13=C12, 0, LN(C13/C12)) -> 0.021941809 | J13: Range | K13: =K12-K11 -> 0.42138498 | M13: =M12+$K$8 -> 0.001462685 | N13: 976 | O13: =N13/$K$16 -> 0.38807157 | P13: =P12+N13 -> 1270 | Q13: =P13/$K$16 -> 0.50497018 | U13: =_xlfn.NORM.DIST(M13,$K$6,$K$8,FALSE) -> 17.399042 | V13: =_xlfn.NORM.DIST(M13,$K$6,$K$8,TRUE) -> 0.50742885 | AJ13: 42017 | AK13: =1 + D13 -> 1.0221843 | AL13: =1 + E13 -> 1.0219418 | AM13: =AVERAGE(D13:D103) -> -0.00074151559 | AN13: =STDEV(D13:D103) -> 0.012753012
B14: 42018 | C14: 24.1 | D14: =((C14-C13)/C13) -> 0.0058430718 | E14: =IF(C14=C13, 0, LN(C14/C13)) -> 0.0058260672 | J14: Sample Variance | K14: =VARPA(D7:D3709) -> 0.00052534686 | M14: =M13+$K$8 -> 0.024387689 | N14: 982 | O14: =N14/$K$16 -> 0.39045726 | P14: =P13+N14 -> 2252 | Q14: =P14/$K$16 -> 0.89542744 | U14: =_xlfn.NORM.DIST(M14,$K$6,$K$8,FALSE) -> 10.358347 | V14: =_xlfn.NORM.DIST(M14,$K$6,$K$8,TRUE) -> 0.84580888 | AJ14: 42018 | AK14: =1 + D14 -> 1.0058431 | AL14: =1 + E14 -> 1.0058261 | AM14: =AVERAGE(D14:D104) -> -0.00096003702 | AN14: =STDEV(D14:D104) -> 0.01252413
B15: 42019 | C15: 23.52 | D15: =((C15-C14)/C14) -> -0.02406639 | E15: =IF(C15=C14, 0, LN(C15/C14)) -> -0.024360717 | J15: Standard Error | K15: =_xlfn.STDEV.S(D7:D3709)/SQRT(K16) -> 0.00045713075 | M15: =M14+$K$8 -> 0.047312694 | N15: 209 | O15: =N15/$K$16 -> 0.083101392 | P15: =P14+N15 -> 2461 | Q15: =P15/$K$16 -> 0.97852883 | U15: =_xlfn.NORM.DIST(M15,$K$6,$K$8,FALSE) -> 2.2686166 | V15: =_xlfn.NORM.DIST(M15,$K$6,$K$8,TRUE) -> 0.97823676 | AJ15: 42019 | AK15: =1 + D15 -> 0.97593361 | AL15: =1 + E15 -> 0.97563928 | AM15: =AVERAGE(D15:D105) -> -0.00093855248 | AN15: =STDEV(D15:D105) -> 0.012537599
B16: 42020 | C16: 23.95 | D16: =((C16-C15)/C15) -> 0.018282313 | E16: =IF(C16=C15, 0, LN(C16/C15)) -> 0.018117201 | J16: Count | K16: =COUNTA(D6:D3709) -> 2515 | M16: =M15+$K$8 -> 0.070237698 | N16: 44 | O16: =N16/$K$16 -> 0.01749503 | P16: =P15+N16 -> 2505 | Q16: =P16/$K$16 -> 0.99602386 | U16: =_xlfn.NORM.DIST(M16,$K$6,$K$8,FALSE) -> 0.18278362 | V16: =_xlfn.NORM.DIST(M16,$K$6,$K$8,TRUE) -> 0.99873037 | AJ16: 42020 | AK16: =1 + D16 -> 1.0182823 | AL16: =1 + E16 -> 1.0181172 | AM16: =AVERAGE(D16:D106) -> -0.00053903736 | AN16: =STDEV(D16:D106) -> 0.012370568
B17: 42024 | C17: 23.92 | D17: =((C17-C16)/C16) -> -0.0012526096 | E17: =IF(C17=C16, 0, LN(C17/C16)) -> -0.0012533948 | M17: =M16+$K$8 -> 0.093162702 | N17: 5 | O17: =N17/$K$16 -> 0.0019880716 | P17: =P16+N17 -> 2510 | Q17: =P17/$K$16 -> 0.99801193 | U17: =_xlfn.NORM.DIST(M17,$K$6,$K$8,FALSE) -> 0.0054177501 | V17: =_xlfn.NORM.DIST(M17,$K$6,$K$8,TRUE) -> 0.99997073 | AJ17: 42024 | AK17: =1 + D17 -> 0.99874739 | AL17: =1 + E17 -> 0.99874661 | AM17: =AVERAGE(D17:D107) -> -0.00075970631 | AN17: =STDEV(D17:D107) -> 0.012209148
B18: 42025 | C18: 24.23 | D18: =((C18-C17)/C17) -> 0.012959866 | E18: =IF(C18=C17, 0, LN(C18/C17)) -> 0.012876606 | M18: =M17+$K$8 -> 0.11608771 | N18: 1 | O18: =N18/$K$16 -> 0.00039761431 | P18: =P17+N18 -> 2511 | Q18: =P18/$K$16 -> 0.99840954 | U18: =_xlfn.NORM.DIST(M18,$K$6,$K$8,FALSE) -> 5.9075332e-05 | V18: =_xlfn.NORM.DIST(M18,$K$6,$K$8,TRUE) -> 0.99999974 | AJ18: 42025 | AK18: =1 + D18 -> 1.0129599 | AL18: =1 + E18 -> 1.0128766 | AM18: =AVERAGE(D18:D108) -> -0.00070634133 | AN18: =STDEV(D18:D108) -> 0.01221758
B19: 42026 | C19: 24.79 | D19: =((C19-C18)/C18) -> 0.023111845 | E19: =IF(C19=C18, 0, LN(C19/C18)) -> 0.022848811 | M19: =M18+$K$8 -> 0.13901271 | N19: 1 | O19: =N19/$K$16 -> 0.00039761431 | P19: =P18+N19 -> 2512 | Q19: =P19/$K$16 -> 0.99880716 | U19: =_xlfn.NORM.DIST(M19,$K$6,$K$8,FALSE) -> 2.3697301e-07 | V19: =_xlfn.NORM.DIST(M19,$K$6,$K$8,TRUE) -> 1 | AJ19: 42026 | AK19: =1 + D19 -> 1.0231118 | AL19: =1 + E19 -> 1.0228488 | AM19: =AVERAGE(D19:D109) -> -0.00078957067 | AN19: =STDEV(D19:D109) -> 0.012149053
B20: 42027 | C20: 24.62 | D20: =((C20-C19)/C19) -> -0.0068576039 | E20: =IF(C20=C19, 0, LN(C20/C19)) -> -0.0068812253 | M20: =M19+$K$8 -> 0.16193772 | N20: 1 | O20: =N20/$K$16 -> 0.00039761431 | P20: =P19+N20 -> 2513 | Q20: =P20/$K$16 -> 0.99920477 | U20: =_xlfn.NORM.DIST(M20,$K$6,$K$8,FALSE) -> 3.4970121e-10 | V20: =_xlfn.NORM.DIST(M20,$K$6,$K$8,TRUE) -> 1 | AJ20: 42027 | AK20: =1 + D20 -> 0.9931424 | AL20: =1 + E20 -> 0.99311877 | AM20: =AVERAGE(D20:D110) -> -0.00080316237 | AN20: =STDEV(D20:D110) -> 0.01212268
B21: 42030 | C21: 25.16 | D21: =((C21-C20)/C20) -> 0.021933387 | E21: =IF(C21=C20, 0, LN(C21/C20)) -> 0.021696311 | M21: =M20+$K$8 -> 0.18486272 | N21: 0 | O21: =N21/$K$16 -> 0 | P21: =P20+N21 -> 2513 | Q21: =P21/$K$16 -> 0.99920477 | U21: =_xlfn.NORM.DIST(M21,$K$6,$K$8,FALSE) -> 1.8984575e-13 | V21: =_xlfn.NORM.DIST(M21,$K$6,$K$8,TRUE) -> 1 | AJ21: 42030 | AK21: =1 + D21 -> 1.0219334 | AL21: =1 + E21 -> 1.0216963 | AM21: =AVERAGE(D21:D111) -> -0.00080461674 | AN21: =STDEV(D21:D111) -> 0.012123422
B22: 42031 | C22: 25.26 | D22: =((C22-C21)/C21) -> 0.0039745628 | E22: =IF(C22=C21, 0, LN(C22/C21)) -> 0.0039666851 | M22: =M21+$K$8 -> 0.20778772 | N22: 1 | O22: =N22/$K$16 -> 0.00039761431 | P22: =P21+N22 -> 2514 | Q22: =P22/$K$16 -> 0.99960239 | U22: =_xlfn.NORM.DIST(M22,$K$6,$K$8,FALSE) -> 3.7914922e-17 | V22: =_xlfn.NORM.DIST(M22,$K$6,$K$8,TRUE) -> 1 | AJ22: 42031 | AK22: =1 + D22 -> 1.0039746 | AL22: =1 + E22 -> 1.0039667 | AM22: =AVERAGE(D22:D112) -> -0.0011955151 | AN22: =STDEV(D22:D112) -> 0.011954426
B23: 42032 | C23: 25.21 | D23: =((C23-C22)/C22) -> -0.0019794141 | E23: =IF(C23=C22, 0, LN(C23/C22)) -> -0.0019813757 | M23: =M22+$K$8 -> 0.23071273 | N23: 0 | O23: =N23/$K$16 -> 0 | P23: =P22+N23 -> 2514 | Q23: =P23/$K$16 -> 0.99960239 | U23: =_xlfn.NORM.DIST(M23,$K$6,$K$8,FALSE) -> 2.7856398e-21 | V23: =_xlfn.NORM.DIST(M23,$K$6,$K$8,TRUE) -> 1 | AJ23: 42032 | AK23: =1 + D23 -> 0.99802059 | AL23: =1 + E23 -> 0.99801862 | AM23: =AVERAGE(D23:D113) -> -0.0013470231 | AN23: =STDEV(D23:D113) -> 0.011975523
B24: 42033 | C24: 25.05 | D24: =((C24-C23)/C23) -> -0.0063466878 | E24: =IF(C24=C23, 0, LN(C24/C23)) -> -0.0063669137 | M24: =M23+$K$8 -> 0.25363773 | N24: 0 | O24: =N24/$K$16 -> 0 | P24: =P23+N24 -> 2514 | Q24: =P24/$K$16 -> 0.99960239 | U24: =_xlfn.NORM.DIST(M24,$K$6,$K$8,FALSE) -> 7.5291382e-26 | V24: =_xlfn.NORM.DIST(M24,$K$6,$K$8,TRUE) -> 1 | AJ24: 42033 | AK24: =1 + D24 -> 0.99365331 | AL24: =1 + E24 -> 0.99363309 | AM24: =AVERAGE(D24:D114) -> -0.0017014717 | AN24: =STDEV(D24:D114) -> 0.012461906
B25: 42034 | C25: 24.87 | D25: =((C25-C24)/C24) -> -0.0071856287 | E25: =IF(C25=C24, 0, LN(C25/C24)) -> -0.0072115697 | M25: =M24+$K$8 -> 0.27656274 | N25: 1 | O25: =N25/$K$16 -> 0.00039761431 | P25: =P24+N25 -> 2515 | Q25: =P25/$K$16 -> 1 | U25: =_xlfn.NORM.DIST(M25,$K$6,$K$8,FALSE) -> 7.4863667e-31 | V25: =_xlfn.NORM.DIST(M25,$K$6,$K$8,TRUE) -> 1 | AJ25: 42034 | AK25: =1 + D25 -> 0.99281437 | AL25: =1 + E25 -> 0.99278843 | AM25: =AVERAGE(D25:D115) -> -0.0016061005 | AN25: =STDEV(D25:D115) -> 0.01245917
B26: 42037 | C26: 24.84 | D26: =((C26-C25)/C25) -> -0.0012062726 | E26: =IF(C26=C25, 0, LN(C26/C25)) -> -0.0012070008 | M26: =M25+$K$8 -> 0.29948774 | N26: 0 | O26: =N26/$K$16 -> 0 | P26: =P25+N26 -> 2515 | Q26: =P26/$K$16 -> 1 | U26: =_xlfn.NORM.DIST(M26,$K$6,$K$8,FALSE) -> 2.7384351e-36 | V26: =_xlfn.NORM.DIST(M26,$K$6,$K$8,TRUE) -> 1 | AJ26: 42037 | AK26: =1 + D26 -> 0.99879373 | AL26: =1 + E26 -> 0.998793 | AM26: =AVERAGE(D26:D116) -> -0.0015015698 | AN26: =STDEV(D26:D116) -> 0.01245174
B27: 42038 | C27: 25.69 | D27: =((C27-C26)/C26) -> 0.034219002 | E27: =IF(C27=C26, 0, LN(C27/C26)) -> 0.033646554 | AJ27: 42038 | AK27: =1 + D27 -> 1.034219 | AL27: =1 + E27 -> 1.0336466 | AM27: =AVERAGE(D27:D117) -> -0.0015546359 | AN27: =STDEV(D27:D117) -> 0.012460754
B28: 42039 | C28: 25.16 | D28: =((C28-C27)/C27) -> -0.020630596 | E28: =IF(C28=C27, 0, LN(C28/C27)) -> -0.020846379 | AJ28: 42039 | AK28: =1 + D28 -> 0.9793694 | AL28: =1 + E28 -> 0.97915362 | AM28: =AVERAGE(D28:D118) -> -0.0019871281 | AN28: =STDEV(D28:D118) -> 0.011874529
B29: 42040 | C29: 24.55 | D29: =((C29-C28)/C28) -> -0.024244833 | E29: =IF(C29=C28, 0, LN(C29/C28)) -> -0.024543578 | AJ29: 42040 | AK29: =1 + D29 -> 0.97575517 | AL29: =1 + E29 -> 0.97545642 | AM29: =AVERAGE(D29:D119) -> -0.0017655774 | AN29: =STDEV(D29:D119) -> 0.011709757
B30: 42041 | C30: 24.3 | D30: =((C30-C29)/C29) -> -0.010183299 | E30: =IF(C30=C29, 0, LN(C30/C29)) -> -0.010235504 | AJ30: 42041 | AK30: =1 + D30 -> 0.9898167 | AL30: =1 + E30 -> 0.9897645 | AM30: =AVERAGE(D30:D120) -> -0.0014888275 | AN30: =STDEV(D30:D120) -> 0.011467678
B31: 42044 | C31: 23.93 | D31: =((C31-C30)/C30) -> -0.015226337 | E31: =IF(C31=C30, 0, LN(C31/C30)) -> -0.015343448 | AJ31: 42044 | AK31: =1 + D31 -> 0.98477366 | AL31: =1 + E31 -> 0.98465655 | AM31: =AVERAGE(D31:D121) -> -0.0012119074 | AN31: =STDEV(D31:D121) -> 0.011559286
B32: 42045 | C32: 23.76 | D32: =((C32-C31)/C31) -> -0.0071040535 | E32: =IF(C32=C31, 0, LN(C32/C31)) -> -0.0071294074 | AJ32: 42045 | AK32: =1 + D32 -> 0.99289595 | AL32: =1 + E32 -> 0.99287059 | AM32: =AVERAGE(D32:D122) -> -0.0010242632 | AN32: =STDEV(D32:D122) -> 0.011467491
B33: 42046 | C33: 24.03 | D33: =((C33-C32)/C32) -> 0.011363636 | E33: =IF(C33=C32, 0, LN(C33/C32)) -> 0.011299555 | AJ33: 42046 | AK33: =1 + D33 -> 1.0113636 | AL33: =1 + E33 -> 1.0112996 | AM33: =AVERAGE(D33:D123) -> -0.00063686139 | AN33: =STDEV(D33:D123) -> 0.011848952
B34: 42047 | C34: 23.34 | D34: =((C34-C33)/C33) -> -0.028714107 | E34: =IF(C34=C33, 0, LN(C34/C33)) -> -0.029134423 | AJ34: 42047 | AK34: =1 + D34 -> 0.97128589 | AL34: =1 + E34 -> 0.97086558 | AM34: =AVERAGE(D34:D124) -> -0.00057924396 | AN34: =STDEV(D34:D124) -> 0.011920486
B35: 42048 | C35: 23.7 | D35: =((C35-C34)/C34) -> 0.015424165 | E35: =IF(C35=C34, 0, LN(C35/C34)) -> 0.015306421 | AJ35: 42048 | AK35: =1 + D35 -> 1.0154242 | AL35: =1 + E35 -> 1.0153064 | AM35: =AVERAGE(D35:D125) -> -0.00029766594 | AN35: =STDEV(D35:D125) -> 0.011545245
B36: 42052 | C36: 23.68 | D36: =((C36-C35)/C35) -> -0.00084388186 | E36: =IF(C36=C35, 0, LN(C36/C35)) -> -0.00084423813 | AJ36: 42052 | AK36: =1 + D36 -> 0.99915612 | AL36: =1 + E36 -> 0.99915576 | AM36: =AVERAGE(D36:D126) -> -0.00044282875 | AN36: =STDEV(D36:D126) -> 0.01142782
B37: 42053 | C37: 23.33 | D37: =((C37-C36)/C36) -> -0.014780405 | E37: =IF(C37=C36, 0, LN(C37/C36)) -> -0.014890724 | AJ37: 42053 | AK37: =1 + D37 -> 0.98521959 | AL37: =1 + E37 -> 0.98510928 | AM37: =AVERAGE(D37:D127) -> -0.00054038619 | AN37: =STDEV(D37:D127) -> 0.011469102
B38: 42054 | C38: 23.48 | D38: =((C38-C37)/C37) -> 0.0064294899 | E38: =IF(C38=C37, 0, LN(C38/C37)) -> 0.0064089089 | AJ38: 42054 | AK38: =1 + D38 -> 1.0064295 | AL38: =1 + E38 -> 1.0064089 | AM38: =AVERAGE(D38:D128) -> -0.00050545825 | AN38: =STDEV(D38:D128) -> 0.011430026
... B2520: 45656 | C2520: 166.51 | D2520: =((C2520-C2519)/C2519) -> -0.022140005 | E2520: =IF(C2520=C2519, 0, LN(C2520/C2519)) -> -0.022388773 | AJ2520: 45656 | AK2520: =1 + D2520 -> 0.97786 | AL2520: =1 + E2520 -> 0.97761123 | AM2520: =AVERAGE(D2520:D2610) -> -0.015123813 | AN2520: =STDEV(D2520:D2610) -> 0.0099223936
B2521: 45657 | C2521: 165.16 | D2521: =((C2521-C2520)/C2520) -> -0.0081076212 | E2521: =IF(C2521=C2520, 0, LN(C2521/C2520)) -> -0.0081406667 | AJ2521: 45657 | AK2521: =1 + D2521 -> 0.99189238 | AL2521: =1 + E2521 -> 0.99185933 | AM2521: =AVERAGE(D2521:D2611) -> -0.0081076212

Sheet Beta
B2: SPX index (x) | E2: Apollo Global Mgmt (y) | I2: Classic Beta | U2: Beta +/-
B3: Date | C3: Price | E3: Date | F3: Price | I3: Z | K3: Y | U3: Z | X3: Y | AI3: Min Beta | AJ3: Max Beta | AM3: Beta | AN3: Beta + / Beta -
B4: 42008 | C4: 2044.8 | E4: 42008 | F4: 23.87 | J4: x | K4: y | M4: Z'*Z | P4: Linest | V4: x | W4: mod x | X4: y | Z4: Z'*Z | AD4: Linest | AI4: =MIN(J6:J532) -> -0.14979602 | AJ4: =MAX(J6:J532) -> 0.12101742 | AL4: -0.15 | AM4: =$M$18*AL4+$M$20 -> -0.21345607 | AN4: =$AA$21*AL4-$Z$17 -> -0.23917787 | BH4: x | BI4: y | BK4: Dates | BL4: Beta 52w | BM4: Volat 52w
B5: 42015 | C5: 2019.4 | E5: 42015 | F5: 23.95 | I5: 1 | J5: 0 | K5: 0 | M5: {=MMULT(TRANSPOSE(I6:J525),I6:J525)} -> 520 | N5: 1.2153812 | P5: {=LINEST(K6:K525,J6:J525,TRUE,TRUE)} -> 1.4345162 | Q5: 0.001721361 | U5: 1 | V5: =C5/C4-1 -> -0.012421753 | W5: =ABS(V5) -> 0.012421753 | X5: =F5/F4-1 -> 0.0033514872 | Z5: {=MMULT(TRANSPOSE(U5:W525),U5:W525)} -> 521 | AA5: 1.2106298 | AB5: 8.577733 | AD5: {=LINEST(X5:X525,V5:W525,TRUE,TRUE)} -> 0.15862893 | AE5: 1.4419675 | AF5: -0.00091158987 | AL5: =AL4+0.5% -> -0.145 | AM5: =$M$18*AL5+$M$20 -> -0.20628349 | AN5: =$AA$21*AL5-$Z$17 -> -0.23117489 | BH5: 0 | BI5: 0 | BK5: 42008 | BL5: / | BM5: /
B6: 42022 | C6: 2051.8 | E6: 42022 | F6: 24.62 | I6: 1 | J6: =C5/C4-1 -> -0.012421753 | K6: =F5/F4-1 -> 0.0033514872 | M6: 1.2153812 | N6: 0.28542858 | P6: 0.072642094 | Q6: 0.0017019054 | U6: 1 | V6: =C6/C5-1 -> 0.01604437 | W6: =ABS(V6) -> 0.01604437 | X6: =F6/F5-1 -> 0.027974948 | Z6: 1.2106298 | AA6: 0.28545115 | AB6: 0.0067477555 | AD6: 0.10166041 | AE6: 0.072620735 | AF6: 0.0023907166 | AL6: =AL5+0.5% -> -0.14 | AM6: =$M$18*AL6+$M$20 -> -0.1991109 | AN6: =$AA$21*AL6-$Z$17 -> -0.2231719 | BH6: =C5/C4-1 -> -0.012421753 | BI6: =F5/F4-1 -> 0.0033514872 | BK6: 42015 | BL6: / | BM6: /
B7: 42029 | C7: 1995 | E7: 42029 | F7: 24.87 | I7: 1 | J7: =C6/C5-1 -> 0.01604437 | K7: =F6/F5-1 -> 0.027974948 | M7: Inverse(Z*Z') | P7: 0.42949826 | Q7: 0.038615809 | U7: 1 | V7: =C7/C6-1 -> -0.02768301 | W7: =ABS(V7) -> 0.02768301 | X7: =F7/F6-1 -> 0.010154346 | Z7: 8.577733 | AA7: 0.0067477555 | AB7: 0.28545115 | AD7: 0.43222683 | AE7: 0.03852548 | AF7: #N/A | AL7: =AL6+0.5% -> -0.135 | AM7: =$M$18*AL7+$M$20 -> -0.19193832 | AN7: =$AA$21*AL7-$Z$17 -> -0.21516892 | BH7: =C6/C5-1 -> 0.01604437 | BI7: =F6/F5-1 -> 0.027974948 | BK7: 42022 | BL7: / | BM7: /
B8: 42036 | C8: 2055.5 | E8: 42036 | F8: 24.3 | I8: 1 | J8: =C7/C6-1 -> -0.02768301 | K8: =F7/F6-1 -> 0.010154346 | M8: {=MINVERSE(M5:N6)} -> 0.0019424084 | N8: -0.0082709542 | P8: 389.97269 | Q8: 518 | U8: 1 | V8: =C8/C7-1 -> 0.030325815 | W8: =ABS(V8) -> 0.030325815 | X8: =F8/F7-1 -> -0.02291918 | Z8: Inverse(Z*Z') | AD8: 197.16809 | AE8: 518 | AF8: #N/A | AL8: =AL7+0.5% -> -0.13 | AM8: =$M$18*AL8+$M$20 -> -0.18476574 | AN8: =$AA$21*AL8-$Z$17 -> -0.20716594 | BH8: =C7/C6-1 -> -0.02768301 | BI8: =F7/F6-1 -> 0.010154346 | BK8: 42029 | BL8: / | BM8: /
B9: 42043 | C9: 2097 | E9: 42043 | F9: 23.7 | I9: 1 | J9: =C8/C7-1 -> 0.030325815 | K9: =F8/F7-1 -> -0.02291918 | M9: -0.0082709542 | N9: 3.5387219 | P9: 0.58151975 | Q9: 0.7724316 | U9: 1 | V9: =C9/C8-1 -> 0.020189735 | W9: =ABS(V9) -> 0.020189735 | X9: =F9/F8-1 -> -0.024691358 | Z9: {=MINVERSE(Z5:AB7)} -> 0.003850881 | AA9: -0.013604165 | AB9: -0.11539638 | AD9: 0.58527872 | AE9: 0.76882214 | AF9: #N/A | AL9: =AL8+0.5% -> -0.125 | AM9: =$M$18*AL9+$M$20 -> -0.17759316 | AN9: =$AA$21*AL9-$Z$17 -> -0.19916296 | BH9: =C8/C7-1 -> 0.030325815 | BI9: =F8/F7-1 -> -0.02291918 | BK9: 42036 | BL9: / | BM9: /
B10: 42050 | C10: 2110.3 | E10: 42050 | F10: 23.5 | I10: 1 | J10: =C9/C8-1 -> 0.020189735 | K10: =F9/F8-1 -> -0.024691358 | M10: Z'*Y | U10: 1 | V10: =C10/C9-1 -> 0.0063423939 | W10: =ABS(V10) -> 0.0063423939 | X10: =F10/F9-1 -> -0.0084388186 | Z10: -0.013604165 | AA10: 3.553245 | AB10: 0.32480677 | AL10: =AL9+0.5% -> -0.12 | AM10: =$M$18*AL10+$M$20 -> -0.17042058 | AN10: =$AA$21*AL10-$Z$17 -> -0.19115998 | BH10: =C9/C8-1 -> 0.020189735 | BI10: =F9/F8-1 -> -0.024691358 | BK10: 42043 | BL10: / | BM10: /
B11: 42057 | C11: 2104.5 | E11: 42057 | F11: 23.32 | I11: 1 | J11: =C10/C9-1 -> 0.0063423939 | K11: =F10/F9-1 -> -0.0084388186 | M11: {=MMULT(TRANSPOSE(I6:J525),K6:K525)} -> 2.6385918 | P11: Beta | Q11: Alpha | U11: 1 | V11: =C11/C10-1 -> -0.0027484244 | W11: =ABS(V11) -> 0.0027484244 | X11: =F11/F10-1 -> -0.0076595745 | Z11: -0.11539638 | AA11: 0.32480677 | AB11: 6.9631796 | AD11: Beta mod | AE11: Beta | AF11: Alpha | AL11: =AL10+0.5% -> -0.115 | AM11: =$M$18*AL11+$M$20 -> -0.163248 | AN11: =$AA$21*AL11-$Z$17 -> -0.183157 | BH11: =C10/C9-1 -> 0.0063423939 | BI11: =F10/F9-1 -> -0.0084388186 | BK11: 42050 | BL11: / | BM11: /
B12: 42064 | C12: 2071.3 | E12: 42064 | F12: 22.28 | I12: 1 | J12: =C11/C10-1 -> -0.0027484244 | K12: =F11/F10-1 -> -0.0076595745 | M12: 0.41154402 | P12: Std err | U12: 1 | V12: =C12/C11-1 -> -0.015775719 | W12: =ABS(V12) -> 0.015775719 | X12: =F12/F11-1 -> -0.044596913 | Z12: Z'*Y | AD12: Std err | AL12: =AL11+0.5% -> -0.11 | AM12: =$M$18*AL12+$M$20 -> -0.15607542 | AN12: =$AA$21*AL12-$Z$17 -> -0.17515401 | BH12: =C11/C10-1 -> -0.0027484244 | BI12: =F11/F10-1 -> -0.0076595745 | BK12: 42057 | BL12: / | BM12: /
B13: 42071 | C13: 2053.4 | E13: 42071 | F13: 22.53 | I13: 1 | J13: =C12/C11-1 -> -0.015775719 | K13: =F12/F11-1 -> -0.044596913 | M13: Alpha e Beta | P13: R^2 | Q13: Std err Y | U13: 1 | V13: =C13/C12-1 -> -0.0086419157 | W13: =ABS(V13) -> 0.0086419157 | X13: =F13/F12-1 -> 0.011220826 | Z13: {=MMULT(TRANSPOSE(U5:W525),X5:X525)} -> 2.6314271 | AD13: R^2 | AE13: Std err Y | AL13: =AL12+0.5% -> -0.105 | AM13: =$M$18*AL13+$M$20 -> -0.14890284 | AN13: =$AA$21*AL13-$Z$17 -> -0.16715103 | BH13: =C12/C11-1 -> -0.015775719 | BI13: =F12/F11-1 -> -0.044596913 | BK13: 42064 | BL13: / | BM13: /
B14: 42078 | C14: 2108.1 | E14: 42078 | F14: 22.24 | I14: 1 | J14: =C13/C12-1 -> -0.0086419157 | K14: =F13/F12-1 -> 0.011220826 | M14: {=MMULT(M8:N9,M11:M12)} -> 0.001721361 | P14: F | Q14: Free | U14: 1 | V14: =C14/C13-1 -> 0.026638745 | W14: =ABS(V14) -> 0.026638745 | X14: =F14/F13-1 -> -0.012871727 | Z14: 0.41157807 | AD14: F | AE14: Free | AL14: =AL13+0.5% -> -0.1 | AM14: =$M$18*AL14+$M$20 -> -0.14173026 | AN14: =$AA$21*AL14-$Z$17 -> -0.15914805 | BH14: =C13/C12-1 -> -0.0086419157 | BI14: =F13/F12-1 -> 0.011220826 | BK14: 42071 | BL14: / | BM14: /
B15: 42085 | C15: 2061 | E15: 42085 | F15: 21.07 | I15: 1 | J15: =C14/C13-1 -> 0.026638745 | K15: =F14/F13-1 -> -0.012871727 | M15: 1.4345162 | P15: SS Reg | Q15: SS Res | U15: 1 | V15: =C15/C14-1 -> -0.022342394 | W15: =ABS(V15) -> 0.022342394 | X15: =F15/F14-1 -> -0.052607914 | Z15: 0.047191482 | AD15: SS Reg | AE15: SS Res | AL15: =AL14+0.5% -> -0.095 | AM15: =$M$18*AL15+$M$20 -> -0.13455768 | AN15: =$AA$21*AL15-$Z$17 -> -0.15114507 | BH15: =C14/C13-1 -> 0.026638745 | BI15: =F14/F13-1 -> -0.012871727 | BK15: 42078 | BL15: / | BM15: /
B16: 42092 | C16: 2067 | E16: 42092 | F16: 21.49 | I16: 1 | J16: =C15/C14-1 -> -0.022342394 | K16: =F15/F14-1 -> -0.052607914 | U16: 1 | V16: =C16/C15-1 -> 0.0029112082 | W16: =ABS(V16) -> 0.0029112082 | X16: =F16/F15-1 -> 0.019933555 | Z16: Alpha, Beta1, Beta2 | AL16: =AL15+0.5% -> -0.09 | AM16: =$M$18*AL16+$M$20 -> -0.1273851 | AN16: =$AA$21*AL16-$Z$17 -> -0.14314209 | BH16: =C15/C14-1 -> -0.022342394 | BI16: =F15/F14-1 -> -0.052607914 | BK16: 42085 | BL16: / | BM16: /
B17: 42099 | C17: 2102.1 | E17: 42099 | F17: 21.25 | I17: 1 | J17: =C16/C15-1 -> 0.0029112082 | K17: =F16/F15-1 -> 0.019933555 | M17: Slope | U17: 1 | V17: =C17/C16-1 -> 0.016981132 | W17: =ABS(V17) -> 0.016981132 | X17: =F17/F16-1 -> -0.011167985 | Z17: {=MMULT(Z9:AB11,Z13:Z15)} -> -0.00091158987 | AL17: =AL16+0.5% -> -0.085 | AM17: =$M$18*AL17+$M$20 -> -0.12021251 | AN17: =$AA$21*AL17-$Z$17 -> -0.1351391 | BH17: =C16/C15-1 -> 0.0029112082 | BI17: =F16/F15-1 -> 0.019933555 | BK17: 42092 | BL17: / | BM17: /
B18: 42106 | C18: 2081.2 | E18: 42106 | F18: 22.06 | I18: 1 | J18: =C17/C16-1 -> 0.016981132 | K18: =F17/F16-1 -> -0.011167985 | M18: =SLOPE(K6:K532,J6:J532) -> 1.4345162 | U18: 1 | V18: =C18/C17-1 -> -0.0099424385 | W18: =ABS(V18) -> 0.0099424385 | X18: =F18/F17-1 -> 0.038117647 | Z18: 1.4419675 | AL18: =AL17+0.5% -> -0.08 | AM18: =$M$18*AL18+$M$20 -> -0.11303993 | AN18: =$AA$21*AL18-$Z$17 -> -0.12713612 | BH18: =C17/C16-1 -> 0.016981132 | BI18: =F17/F16-1 -> -0.011167985 | BK18: 42099 | BL18: / | BM18: /
B19: 42113 | C19: 2117.7 | E19: 42113 | F19: 22.02 | I19: 1 | J19: =C18/C17-1 -> -0.0099424385 | K19: =F18/F17-1 -> 0.038117647 | M19: Intercept | U19: 1 | V19: =C19/C18-1 -> 0.017537959 | W19: =ABS(V19) -> 0.017537959 | X19: =F19/F18-1 -> -0.0018132366 | Z19: 0.15862893 | AL19: =AL18+0.5% -> -0.075 | AM19: =$M$18*AL19+$M$20 -> -0.10586735 | AN19: =$AA$21*AL19-$Z$17 -> -0.11913314 | BH19: =C18/C17-1 -> -0.0099424385 | BI19: =F18/F17-1 -> 0.038117647 | BK19: 42106 | BL19: / | BM19: /
B20: 42120 | C20: 2108.3 | E20: 42120 | F20: 22.88 | I20: 1 | J20: =C19/C18-1 -> 0.017537959 | K20: =F19/F18-1 -> -0.0018132366 | M20: =INTERCEPT(K6:K532,J6:J532) -> 0.001721361 | U20: 1 | V20: =C20/C19-1 -> -0.0044387779 | W20: =ABS(V20) -> 0.0044387779 | X20: =F20/F19-1 -> 0.039055404 | AL20: =AL19+0.5% -> -0.07 | AM20: =$M$18*AL20+$M$20 -> -0.098694772 | AN20: =$AA$21*AL20-$Z$17 -> -0.11113016 | BH20: =C19/C18-1 -> 0.017537959 | BI20: =F19/F18-1 -> -0.0018132366 | BK20: 42113 | BL20: / | BM20: /
B21: 42127 | C21: 2116.1 | E21: 42127 | F21: 21.95 | I21: 1 | J21: =C20/C19-1 -> -0.0044387779 | K21: =F20/F19-1 -> 0.039055404 | U21: 1 | V21: =C21/C20-1 -> 0.0036996632 | W21: =ABS(V21) -> 0.0036996632 | X21: =F21/F20-1 -> -0.040646853 | Z21: Beta + | AA21: =Z18+Z19 -> 1.6005964 | AL21: =AL20+0.5% -> -0.065 | AM21: =$M$18*AL21+$M$20 -> -0.091522191 | AN21: =$AA$21*AL21-$Z$17 -> -0.10312718 | BH21: =C20/C19-1 -> -0.0044387779 | BI21: =F20/F19-1 -> 0.039055404 | BK21: 42120 | BL21: / | BM21: /
B22: 42134 | C22: 2122.7 | E22: 42134 | F22: 21.87 | I22: 1 | J22: =C21/C20-1 -> 0.0036996632 | K22: =F21/F20-1 -> -0.040646853 | M22: Jensen Alpha | U22: 1 | V22: =C22/C21-1 -> 0.0031189452 | W22: =ABS(V22) -> 0.0031189452 | X22: =F22/F21-1 -> -0.0036446469 | Z22: Beta - | AA22: =Z18-Z19 -> 1.2833385 | AL22: =AL21+0.5% -> -0.06 | AM22: =$M$18*AL22+$M$20 -> -0.08434961 | AN22: =$AA$21*AL22-$Z$17 -> -0.095124194 | BH22: =C21/C20-1 -> 0.0036996632 | BI22: =F21/F20-1 -> -0.040646853 | BK22: 42127 | BL22: / | BM22: /
B23: 42141 | C23: 2126.1 | E23: 42141 | F23: 21.75 | I23: 1 | J23: =C22/C21-1 -> 0.0031189452 | K23: =F22/F21-1 -> -0.0036446469 | M23: =M20-N25/52*(1-M18) -> 0.0020973846 | N23: n | U23: 1 | V23: =C23/C22-1 -> 0.0016017336 | W23: =ABS(V23) -> 0.0016017336 | X23: =F23/F22-1 -> -0.0054869684 | AL23: =AL22+0.5% -> -0.055 | AM23: =$M$18*AL23+$M$20 -> -0.077177029 | AN23: =$AA$21*AL23-$Z$17 -> -0.087121212 | BH23: =C22/C21-1 -> 0.0031189452 | BI23: =F22/F21-1 -> -0.0036446469 | BK23: 42134 | BL23: / | BM23: /
B24: 42148 | C24: 2107.4 | E24: 42148 | F24: 22.2 | I24: 1 | J24: =C23/C22-1 -> 0.0016017336 | K24: =F23/F22-1 -> -0.0054869684 | U24: 1 | V24: =C24/C23-1 -> -0.0087954471 | W24: =ABS(V24) -> 0.0087954471 | X24: =F24/F23-1 -> 0.020689655 | AL24: =AL23+0.5% -> -0.05 | AM24: =$M$18*AL24+$M$20 -> -0.070004448 | AN24: =$AA$21*AL24-$Z$17 -> -0.07911823 | BH24: =C23/C22-1 -> 0.0016017336 | BI24: =F23/F22-1 -> -0.0054869684 | BK24: 42141 | BL24: / | BM24: /
B25: 42155 | C25: 2092.8 | E25: 42155 | F25: 22.42 | I25: 1 | J25: =C24/C23-1 -> -0.0087954471 | K25: =F24/F23-1 -> 0.020689655 | M25: 10yr bond | N25: 0.045 | U25: 1 | V25: =C25/C24-1 -> -0.0069279681 | W25: =ABS(V25) -> 0.0069279681 | X25: =F25/F24-1 -> 0.0099099099 | AL25: =AL24+0.5% -> -0.045 | AM25: =$M$18*AL25+$M$20 -> -0.062831867 | AN25: =$AA$21*AL25-$Z$17 -> -0.071115248 | BH25: =C24/C23-1 -> -0.0087954471 | BI25: =F24/F23-1 -> 0.020689655 | BK25: 42148 | BL25: / | BM25: /
B26: 42162 | C26: 2094.1 | E26: 42162 | F26: 21.41 | I26: 1 | J26: =C25/C24-1 -> -0.0069279681 | K26: =F25/F24-1 -> 0.0099099099 | U26: 1 | V26: =C26/C25-1 -> 0.00062117737 | W26: =ABS(V26) -> 0.00062117737 | X26: =F26/F25-1 -> -0.045049063 | AL26: =AL25+0.5% -> -0.04 | AM26: =$M$18*AL26+$M$20 -> -0.055659286 | AN26: =$AA$21*AL26-$Z$17 -> -0.063112266 | BH26: =C25/C24-1 -> -0.0069279681 | BI26: =F25/F24-1 -> 0.0099099099 | BK26: 42155 | BL26: / | BM26: /
B27: 42169 | C27: 2110 | E27: 42169 | F27: 21.67 | I27: 1 | J27: =C26/C25-1 -> 0.00062117737 | K27: =F26/F25-1 -> -0.045049063 | U27: 1 | V27: =C27/C26-1 -> 0.0075927606 | W27: =ABS(V27) -> 0.0075927606 | X27: =F27/F26-1 -> 0.012143858 | AL27: =AL26+0.5% -> -0.035 | AM27: =$M$18*AL27+$M$20 -> -0.048486705 | AN27: =$AA$21*AL27-$Z$17 -> -0.055109284 | BH27: =C26/C25-1 -> 0.00062117737 | BI27: =F26/F25-1 -> -0.045049063 | BK27: 42162 | BL27: / | BM27: /
B28: 42176 | C28: 2101.5 | E28: 42176 | F28: 22.41 | I28: 1 | J28: =C27/C26-1 -> 0.0075927606 | K28: =F27/F26-1 -> 0.012143858 | U28: 1 | V28: =C28/C27-1 -> -0.004028436 | W28: =ABS(V28) -> 0.004028436 | X28: =F28/F27-1 -> 0.034148593 | AL28: =AL27+0.5% -> -0.03 | AM28: =$M$18*AL28+$M$20 -> -0.041314124 | AN28: =$AA$21*AL28-$Z$17 -> -0.047106302 | BH28: =C27/C26-1 -> 0.0075927606 | BI28: =F27/F26-1 -> 0.012143858 | BK28: 42169 | BL28: / | BM28: /
B29: 42183 | C29: 2076.8 | E29: 42183 | F29: 22.15 | I29: 1 | J29: =C28/C27-1 -> -0.004028436 | K29: =F28/F27-1 -> 0.034148593 | U29: 1 | V29: =C29/C28-1 -> -0.011753509 | W29: =ABS(V29) -> 0.011753509 | X29: =F29/F28-1 -> -0.011601963 | AL29: =AL28+0.5% -> -0.025 | AM29: =$M$18*AL29+$M$20 -> -0.034141544 | AN29: =$AA$21*AL29-$Z$17 -> -0.03910332 | BH29: =C28/C27-1 -> -0.004028436 | BI29: =F28/F27-1 -> 0.034148593 | BK29: 42176 | BL29: / | BM29: /
B30: 42190 | C30: 2076.6 | E30: 42190 | F30: 21.85 | I30: 1 | J30: =C29/C28-1 -> -0.011753509 | K30: =F29/F28-1 -> -0.011601963 | U30: 1 | V30: =C30/C29-1 -> -9.6302003e-05 | W30: =ABS(V30) -> 9.6302003e-05 | X30: =F30/F29-1 -> -0.013544018 | AL30: =AL29+0.5% -> -0.02 | AM30: =$M$18*AL30+$M$20 -> -0.026968963 | AN30: =$AA$21*AL30-$Z$17 -> -0.031100338 | BH30: =C29/C28-1 -> -0.011753509 | BI30: =F29/F28-1 -> -0.011601963 | BK30: 42183 | BL30: / | BM30: /
B31: 42197 | C31: 2126.6 | E31: 42197 | F31: 22.16 | I31: 1 | J31: =C30/C29-1 -> -9.6302003e-05 | K31: =F30/F29-1 -> -0.013544018 | U31: 1 | V31: =C31/C30-1 -> 0.02407782 | W31: =ABS(V31) -> 0.02407782 | X31: =F31/F30-1 -> 0.014187643 | AL31: =AL30+0.5% -> -0.015 | AM31: =$M$18*AL31+$M$20 -> -0.019796382 | AN31: =$AA$21*AL31-$Z$17 -> -0.023097356 | BH31: =C30/C29-1 -> -9.6302003e-05 | BI31: =F30/F29-1 -> -0.013544018 | BK31: 42190 | BL31: / | BM31: /
B32: 42204 | C32: 2079.7 | E32: 42204 | F32: 20.36 | I32: 1 | J32: =C31/C30-1 -> 0.02407782 | K32: =F31/F30-1 -> 0.014187643 | U32: 1 | V32: =C32/C31-1 -> -0.022053983 | W32: =ABS(V32) -> 0.022053983 | X32: =F32/F31-1 -> -0.081227437 | AL32: =AL31+0.5% -> -0.01 | AM32: =$M$18*AL32+$M$20 -> -0.012623801 | AN32: =$AA$21*AL32-$Z$17 -> -0.015094374 | BH32: =C31/C30-1 -> 0.02407782 | BI32: =F31/F30-1 -> 0.014187643 | BK32: 42197 | BL32: / | BM32: /
B33: 42211 | C33: 2103.8 | E33: 42211 | F33: 20.57 | I33: 1 | J33: =C32/C31-1 -> -0.022053983 | K33: =F32/F31-1 -> -0.081227437 | U33: 1 | V33: =C33/C32-1 -> 0.01158821 | W33: =ABS(V33) -> 0.01158821 | X33: =F33/F32-1 -> 0.010314342 | AL33: =AL32+0.5% -> -0.005 | AM33: =$M$18*AL33+$M$20 -> -0.0054512199 | AN33: =$AA$21*AL33-$Z$17 -> -0.0070913921 | BH33: =C32/C31-1 -> -0.022053983 | BI33: =F32/F31-1 -> -0.081227437 | BK33: 42204 | BL33: / | BM33: /
B34: 42218 | C34: 2077.6 | E34: 42218 | F34: 21.18 | I34: 1 | J34: =C33/C32-1 -> 0.01158821 | K34: =F33/F32-1 -> 0.010314342 | U34: 1 | V34: =C34/C33-1 -> -0.012453655 | W34: =ABS(V34) -> 0.012453655 | X34: =F34/F33-1 -> 0.029654837 | AL34: =AL33+0.5% -> 7.1123663e-17 | AM34: =$M$18*AL34+$M$20 -> 0.001721361 | AN34: =$AA$21*AL34-$Z$17 -> 0.00091158987 | BH34: =C33/C32-1 -> 0.01158821 | BI34: =F33/F32-1 -> 0.010314342 | BK34: 42211 | BL34: / | BM34: /
B35: 42225 | C35: 2091.5 | E35: 42225 | F35: 20.71 | I35: 1 | J35: =C34/C33-1 -> -0.012453655 | K35: =F34/F33-1 -> 0.029654837 | U35: 1 | V35: =C35/C34-1 -> 0.006690412 | W35: =ABS(V35) -> 0.006690412 | X35: =F35/F34-1 -> -0.022190746 | AL35: =AL34+0.5% -> 0.005 | AM35: =$M$18*AL35+$M$20 -> 0.0088939419 | AN35: =$AA$21*AL35-$Z$17 -> 0.0089145718 | BH35: =C34/C33-1 -> -0.012453655 | BI35: =F34/F33-1 -> 0.029654837 | BK35: 42218 | BL35: / | BM35: /
B36: 42232 | C36: 1970.9 | E36: 42232 | F36: 18.84 | I36: 1 | J36: =C35/C34-1 -> 0.006690412 | K36: =F35/F34-1 -> -0.022190746 | U36: 1 | V36: =C36/C35-1 -> -0.057661965 | W36: =ABS(V36) -> 0.057661965 | X36: =F36/F35-1 -> -0.090294544 | AL36: =AL35+0.5% -> 0.01 | AM36: =$M$18*AL36+$M$20 -> 0.016066523 | AN36: =$AA$21*AL36-$Z$17 -> 0.016917554 | BH36: =C35/C34-1 -> 0.006690412 | BI36: =F35/F34-1 -> -0.022190746 | BK36: 42225 | BL36: / | BM36: /
B37: 42239 | C37: 1988.9 | E37: 42239 | F37: 19.05 | I37: 1 | J37: =C36/C35-1 -> -0.057661965 | K37: =F36/F35-1 -> -0.090294544 | U37: 1 | V37: =C37/C36-1 -> 0.0091328835 | W37: =ABS(V37) -> 0.0091328835 | X37: =F37/F36-1 -> 0.011146497 | AL37: =AL36+0.5% -> 0.015 | AM37: =$M$18*AL37+$M$20 -> 0.023239104 | AN37: =$AA$21*AL37-$Z$17 -> 0.024920536 | BH37: =C36/C35-1 -> -0.057661965 | BI37: =F36/F35-1 -> -0.090294544 | BK37: 42232 | BL37: / | BM37: /
... B56: 42372 | C56: 1922 | E56: 42372 | F56: 14 | I56: 1 | J56: =C55/C54-1 -> -0.0082969432 | K56: =F55/F54-1 -> -0.026923077 | U56: 1 | V56: =C56/C55-1 -> -0.059640883 | W56: =ABS(V56) -> 0.059640883 | X56: =F56/F55-1 -> -0.07773386 | AL56: =AL55+0.5% -> 0.11 | AM56: =$M$18*AL56+$M$20 -> 0.15951814 | AN56: =$AA$21*AL56-$Z$17 -> 0.17697719 | BH56: =C55/C54-1 -> -0.0082969432 | BI56: =F55/F54-1 -> -0.026923077 | BK56: 42365 | BL56: / | BM56: /
B57: 42379 | C57: 1880.3 | E57: 42379 | F57: 13.38 | I57: 1 | J57: =C56/C55-1 -> -0.059640883 | K57: =F56/F55-1 -> -0.07773386 | U57: 1 | V57: =C57/C56-1 -> -0.02169615 | W57: =ABS(V57) -> 0.02169615 | X57: =F57/F56-1 -> -0.044285714 | AL57: =AL56+0.5% -> 0.115 | AM57: =$M$18*AL57+$M$20 -> 0.16669072 | AN57: =$AA$21*AL57-$Z$17 -> 0.18498017 | BH57: =C56/C55-1 -> -0.059640883 | BI57: =F56/F55-1 -> -0.07773386 | BK57: 42372 | BL57: =SLOPE(BI5:BI57,BH5:BH57) -> 0.74237049 | BM57: =STDEV(BI5:BI57) -> 0.032077309
B58: 42386 | C58: 1906.9 | E58: 42386 | F58: 13.8 | I58: 1 | J58: =C57/C56-1 -> -0.02169615 | K58: =F57/F56-1 -> -0.044285714 | U58: 1 | V58: =C58/C57-1 -> 0.014146679 | W58: =ABS(V58) -> 0.014146679 | X58: =F58/F57-1 -> 0.031390135 | AL58: =AL57+0.5% -> 0.12 | AM58: =$M$18*AL58+$M$20 -> 0.1738633 | AN58: =$AA$21*AL58-$Z$17 -> 0.19298316 | BH58: =C57/C56-1 -> -0.02169615 | BI58: =F57/F56-1 -> -0.044285714 | BK58: 42379 | BL58: =SLOPE(BI6:BI58,BH6:BH58) -> 0.75963649 | BM58: =STDEV(BI6:BI58) -> 0.032400223
B59: 42393 | C59: 1940.2 | E59: 42393 | F59: 13.58 | I59: 1 | J59: =C58/C57-1 -> 0.014146679 | K59: =F58/F57-1 -> 0.031390135 | U59: 1 | V59: =C59/C58-1 -> 0.017462898 | W59: =ABS(V59) -> 0.017462898 | X59: =F59/F58-1 -> -0.015942029 | AL59: =AL58+0.5% -> 0.125 | AM59: =$M$18*AL59+$M$20 -> 0.18103588 | AN59: =$AA$21*AL59-$Z$17 -> 0.20098614 | BH59: =C58/C57-1 -> 0.014146679 | BI59: =F58/F57-1 -> 0.031390135 | BK59: 42386 | BL59: =SLOPE(BI7:BI59,BH7:BH59) -> 0.79132828 | BM59: =STDEV(BI7:BI59) -> 0.032853758
...

Sheet Pair trade
B2: Parameters | F2: Apollo Global Mgmt | H2: Blackstone | Q2: Last Price | R2: Beta | T2: Investment | V2: 100000
B3: Date | C3: 44562 | E3: Dates | F3: Price | G3: Var % | H3: Price | I3: Var % | J3: Ratio Norm | K3: RN-Std | L3: RN+Std | O3: Sell | P3: APO US | Q3: =F756 -> 165.16 | R3: =Beta!M15 -> 1.4345162 | T3: $$ Neutral | U3: APO US | V3: =ROUND(V2/Q3,0) -> 605 | AE3: Dates | AF3: ln APO US | AG3: ln BX US
C4: 45657 | E4: 44564 | F4: 71.53 | H4: 126.63 | J4: =F4/$F$4*$H$4/H4 -> 1 | K4: =AVERAGE($J$5:$J$756)-1.5*_xlfn.STDEV.S($J$5:$J$756) -> 0.94221126 | L4: =AVERAGE($J$5:$J$756)+_xlfn.STDEV.S($J$5:$J$756) -> 1.5816901 | O4: Buy | P4: BX US | Q4: =H756 -> 172.42 | R4: 1.54 | U4: BX US | V4: =ROUND(V2/Q4,0) -> 580 | AE4: 44564 | AF4: =LN(F4) -> 4.2701169 | AG4: =LN(H4) -> 4.8412694 | AI4: Slope | AJ4: =SLOPE(AG4:AG756,AF4:AF756) -> 0.5127802
B5: Indip. | C5: Blackstone | E5: 44565 | F5: 73.56 | G5: =F5/F4-1 -> 0.028379701 | H5: 124.94 | I5: =H5/H4-1 -> -0.013345969 | J5: =F5/$F$4*$H$4/H5 -> 1.0422901 | K5: =AVERAGE($J$5:$J$756)-1.5*_xlfn.STDEV.S($J$5:$J$756) -> 0.94221126 | L5: =AVERAGE($J$5:$J$756)+_xlfn.STDEV.S($J$5:$J$756) -> 1.5816901 | P5: Cur Ratio | Q5: =Q3/Q4 -> 0.95789352 | T5: Beta Neutral | U5: APO US | V5: =V3 -> 605 | AE5: 44565 | AF5: =LN(F5) -> 4.2981014 | AG5: =LN(H5) -> 4.8278336 | AI5: Intercept | AJ5: =INTERCEPT(AG4:AG2256,AF4:AF2256) -> 2.4529692
B6: Dip. | C6: Apollo Global Mgmt | E6: 44566 | F6: 69.6 | G6: =F6/F5-1 -> -0.053833605 | H6: 117.79 | I6: =H6/H5-1 -> -0.057227469 | J6: =F6/$F$4*$H$4/H6 -> 1.0460422 | K6: =AVERAGE($J$5:$J$756)-1.5*_xlfn.STDEV.S($J$5:$J$756) -> 0.94221126 | L6: =AVERAGE($J$5:$J$756)+_xlfn.STDEV.S($J$5:$J$756) -> 1.5816901 | P6: Cur Corr | Q6: =CORREL(G4:G756,I4:I756) -> 0.69515429 | U6: BX US | V6: =ROUND(V2*R3/R4/Q4,0) -> 540 | AE6: 44566 | AF6: =LN(F6) -> 4.2427646 | AG6: =LN(H6) -> 4.7689034
E7: 44567 | F7: 69.57 | G7: =F7/F6-1 -> -0.00043103448 | H7: 119.16 | I7: =H7/H6-1 -> 0.011630868 | J7: =F7/$F$4*$H$4/H7 -> 1.03357 | K7: =AVERAGE($J$5:$J$756)-1.5*_xlfn.STDEV.S($J$5:$J$756) -> 0.94221126 | L7: =AVERAGE($J$5:$J$756)+_xlfn.STDEV.S($J$5:$J$756) -> 1.5816901 | T7: Corr Neutral | U7: APO US | V7: =V5 -> 605 | AE7: 44567 | AF7: =LN(F7) -> 4.2423334 | AG7: =LN(H7) -> 4.7804671
E8: 44568 | F8: 68.96 | G8: =F8/F7-1 -> -0.0087681472 | H8: 116.65 | I8: =H8/H7-1 -> -0.021064115 | J8: =F8/$F$4*$H$4/H8 -> 1.0465522 | K8: =AVERAGE($J$5:$J$756)-1.5*_xlfn.STDEV.S($J$5:$J$756) -> 0.94221126 | L8: =AVERAGE($J$5:$J$756)+_xlfn.STDEV.S($J$5:$J$756) -> 1.5816901 | U8: BX US | V8: =ROUND(V2*Q6/Q4,0) -> 403 | AE8: 44568 | AF8: =LN(F8) -> 4.2335266 | AG8: =LN(H8) -> 4.759178
E9: 44571 | F9: 68.35 | G9: =F9/F8-1 -> -0.0088457077 | H9: 114.72 | I9: =H9/H8-1 -> -0.016545221 | J9: =F9/$F$4*$H$4/H9 -> 1.0547457 | K9: =AVERAGE($J$5:$J$756)-1.5*_xlfn.STDEV.S($J$5:$J$756) -> 0.94221126 | L9: =AVERAGE($J$5:$J$756)+_xlfn.STDEV.S($J$5:$J$756) -> 1.5816901 | AE9: 44571 | AF9: =LN(F9) -> 4.2246416 | AG9: =LN(H9) -> 4.7424944
E10: 44572 | F10: 70.58 | G10: =F10/F9-1 -> 0.032626189 | H10: 121.3 | I10: =H10/H9-1 -> 0.057357043 | J10: =F10/$F$4*$H$4/H10 -> 1.0300759 | K10: =AVERAGE($J$5:$J$756)-1.5*_xlfn.STDEV.S($J$5:$J$756) -> 0.94221126 | L10: =AVERAGE($J$5:$J$756)+_xlfn.STDEV.S($J$5:$J$756) -> 1.5816901 | AE10: 44572 | AF10: =LN(F10) -> 4.2567468 | AG10: =LN(H10) -> 4.7982668
E11: 44573 | F11: 70.76 | G11: =F11/F10-1 -> 0.0025502975 | H11: 122.34 | I11: =H11/H10-1 -> 0.008573784 | J11: =F11/$F$4*$H$4/H11 -> 1.023924 | K11: =AVERAGE($J$5:$J$756)-1.5*_xlfn.STDEV.S($J$5:$J$756) -> 0.94221126 | L11: =AVERAGE($J$5:$J$756)+_xlfn.STDEV.S($J$5:$J$756) -> 1.5816901 | AE11: 44573 | AF11: =LN(F11) -> 4.2592939 | AG11: =LN(H11) -> 4.8068041
E12: 44574 | F12: 69.55 | G12: =F12/F11-1 -> -0.017100057 | H12: 118.94 | I12: =H12/H11-1 -> -0.027791401 | J12: =F12/$F$4*$H$4/H12 -> 1.0351841 | K12: =AVERAGE($J$5:$J$756)-1.5*_xlfn.STDEV.S($J$5:$J$756) -> 0.94221126 | L12: =AVERAGE($J$5:$J$756)+_xlfn.STDEV.S($J$5:$J$756) -> 1.5816901 | AE12: 44574 | AF12: =LN(F12) -> 4.2420459 | AG12: =LN(H12) -> 4.7786192
E13: 44575 | F13: 68.83 | G13: =F13/F12-1 -> -0.010352265 | H13: 116.12 | I13: =H13/H12-1 -> -0.023709433 | J13: =F13/$F$4*$H$4/H13 -> 1.049347 | K13: =AVERAGE($J$5:$J$756)-1.5*_xlfn.STDEV.S($J$5:$J$756) -> 0.94221126 | L13: =AVERAGE($J$5:$J$756)+_xlfn.STDEV.S($J$5:$J$756) -> 1.5816901 | AE13: 44575 | AF13: =LN(F13) -> 4.2316397 | AG13: =LN(H13) -> 4.7546241
E14: 44579 | F14: 67.65 | G14: =F14/F13-1 -> -0.017143687 | H14: 113.92 | I14: =H14/H13-1 -> -0.018945918 | J14: =F14/$F$4*$H$4/H14 -> 1.0512747 | K14: =AVERAGE($J$5:$J$756)-1.5*_xlfn.STDEV.S($J$5:$J$756) -> 0.94221126 | L14: =AVERAGE($J$5:$J$756)+_xlfn.STDEV.S($J$5:$J$756) -> 1.5816901 | AE14: 44579 | AF14: =LN(F14) -> 4.2143474 | AG14: =LN(H14) -> 4.7354964
E15: 44580 | F15: 67.05 | G15: =F15/F14-1 -> -0.0088691796 | H15: 112.26 | I15: =H15/H14-1 -> -0.014571629 | J15: =F15/$F$4*$H$4/H15 -> 1.0573582 | K15: =AVERAGE($J$5:$J$756)-1.5*_xlfn.STDEV.S($J$5:$J$756) -> 0.94221126 | L15: =AVERAGE($J$5:$J$756)+_xlfn.STDEV.S($J$5:$J$756) -> 1.5816901 | AE15: 44580 | AF15: =LN(F15) -> 4.2054386 | AG15: =LN(H15) -> 4.7208176
E16: 44581 | F16: 67 | G16: =F16/F15-1 -> -0.00074571216 | H16: 111.56 | I16: =H16/H15-1 -> -0.0062355247 | J16: =F16/$F$4*$H$4/H16 -> 1.0631993 | K16: =AVERAGE($J$5:$J$756)-1.5*_xlfn.STDEV.S($J$5:$J$756) -> 0.94221126 | L16: =AVERAGE($J$5:$J$756)+_xlfn.STDEV.S($J$5:$J$756) -> 1.5816901 | AE16: 44581 | AF16: =LN(F16) -> 4.2046926 | AG16: =LN(H16) -> 4.7145626
E17: 44582 | F17: 65.9 | G17: =F17/F16-1 -> -0.01641791 | H17: 109.78 | I17: =H17/H16-1 -> -0.01595554 | J17: =F17/$F$4*$H$4/H17 -> 1.0626997 | K17: =AVERAGE($J$5:$J$756)-1.5*_xlfn.STDEV.S($J$5:$J$756) -> 0.94221126 | L17: =AVERAGE($J$5:$J$756)+_xlfn.STDEV.S($J$5:$J$756) -> 1.5816901 | AE17: 44582 | AF17: =LN(F17) -> 4.1881384 | AG17: =LN(H17) -> 4.6984784
E18: 44585 | F18: 65.35 | G18: =F18/F17-1 -> -0.0083459788 | H18: 109.39 | I18: =H18/H17-1 -> -0.0035525597 | J18: =F18/$F$4*$H$4/H18 -> 1.0575876 | K18: =AVERAGE($J$5:$J$756)-1.5*_xlfn.STDEV.S($J$5:$J$756) -> 0.94221126 | L18: =AVERAGE($J$5:$J$756)+_xlfn.STDEV.S($J$5:$J$756) -> 1.5816901 | AE18: 44585 | AF18: =LN(F18) -> 4.1797574 | AG18: =LN(H18) -> 4.6949195
E19: 44586 | F19: 64.15 | G19: =F19/F18-1 -> -0.018362663 | H19: 110.24 | I19: =H19/H18-1 -> 0.0077703629 | J19: =F19/$F$4*$H$4/H19 -> 1.0301627 | K19: =AVERAGE($J$5:$J$756)-1.5*_xlfn.STDEV.S($J$5:$J$756) -> 0.94221126 | L19: =AVERAGE($J$5:$J$756)+_xlfn.STDEV.S($J$5:$J$756) -> 1.5816901 | AE19: 44586 | AF19: =LN(F19) -> 4.1612241 | AG19: =LN(H19) -> 4.7026598
E20: 44587 | F20: 63.55 | G20: =F20/F19-1 -> -0.0093530787 | H20: 111.47 | I20: =H20/H19-1 -> 0.011157475 | J20: =F20/$F$4*$H$4/H20 -> 1.0092667 | K20: =AVERAGE($J$5:$J$756)-1.5*_xlfn.STDEV.S($J$5:$J$756) -> 0.94221126 | L20: =AVERAGE($J$5:$J$756)+_xlfn.STDEV.S($J$5:$J$756) -> 1.5816901 | AE20: 44587 | AF20: =LN(F20) -> 4.151827 | AG20: =LN(H20) -> 4.7137555
... E756: 45657 | F756: 165.16 | G756: =F756/F755-1 -> -0.0081076212 | H756: 172.42 | I756: =H756/H755-1 -> 0.0021505376 | J756: =F756/$F$4*$H$4/H756 -> 1.6957648 | K756: =AVERAGE($J$5:$J$756)-1.5*_xlfn.STDEV.S($J$5:$J$756) -> 0.94221126 | L756: =AVERAGE($J$5:$J$756)+_xlfn.STDEV.S($J$5:$J$756) -> 1.5816901 | AE756: 45657 | AF756: =LN(F756) -> 5.1069147 | AG756: =LN(H756) -> 5.1499334

Sheet Moving Avgs
AZ1: =2/(20+1) -> 0.095238095 | BA1: =2/(50+1) -> 0.039215686 | CE1: =2/(200+1) -> 0.0099502488
B2: Dates | C2: Prices | D2: MA 20d | E2: MA 50d | F2: Diff | Z2: Dates | AA2: Prices | AB2: MA 200d | AX2: Dates | AY2: Prices | AZ2: EMA 20d | BA2: EMA 50d | BC2: Diff 20d | BD2: Diff50d | BE2: Zero Lag 20d | BF2: Zero Lag 50d | CC2: Dates | CD2: Prices | CE2: EMA 200d | CG2: Diff | CH2: Zero Lag 200d
B3: 44929 | C3: 62.81 | Z3: 43102 | AA3: 33.6 | AX3: 44929 | AY3: 62.81 | CC3: 43102 | CD3: 33.6
B4: 44930 | C4: 64.36 | Z4: 43103 | AA4: 34.27 | AX4: 44930 | AY4: 64.36 | CC4: 43103 | CD4: 34.27
B5: 44931 | C5: 62.95 | Z5: 43104 | AA5: 34.31 | AX5: 44931 | AY5: 62.95 | CC5: 43104 | CD5: 34.31
B6: 44932 | C6: 64.33 | Z6: 43105 | AA6: 34.48 | AX6: 44932 | AY6: 64.33 | CC6: 43105 | CD6: 34.48
B7: 44935 | C7: 65.32 | Z7: 43108 | AA7: 34.92 | AX7: 44935 | AY7: 65.32 | CC7: 43108 | CD7: 34.92
B8: 44936 | C8: 66.52 | Z8: 43109 | AA8: 35.69 | AX8: 44936 | AY8: 66.52 | CC8: 43109 | CD8: 35.69
B9: 44937 | C9: 67.68 | Z9: 43110 | AA9: 35.56 | AX9: 44937 | AY9: 67.68 | CC9: 43110 | CD9: 35.56
B10: 44938 | C10: 68.44 | Z10: 43111 | AA10: 35.89 | AX10: 44938 | AY10: 68.44 | CC10: 43111 | CD10: 35.89
B11: 44939 | C11: 69.71 | Z11: 43112 | AA11: 36.19 | AX11: 44939 | AY11: 69.71 | CC11: 43112 | CD11: 36.19
B12: 44943 | C12: 69.09 | Z12: 43116 | AA12: 35.08 | AX12: 44943 | AY12: 69.09 | CC12: 43116 | CD12: 35.08
B13: 44944 | C13: 68.03 | Z13: 43117 | AA13: 35.42 | AX13: 44944 | AY13: 68.03 | CC13: 43117 | CD13: 35.42
B14: 44945 | C14: 65.78 | Z14: 43118 | AA14: 35.07 | AX14: 44945 | AY14: 65.78 | CC14: 43118 | CD14: 35.07
... B22: 44957 | C22: 70.78 | Z22: 43130 | AA22: 35.5 | AX22: 44957 | AY22: 70.78 | CC22: 43130 | CD22: 35.5
B23: 44958 | C23: 72.52 | D23: =AVERAGE(C3:C23) -> 67.620952 | Z23: 43131 | AA23: 35.75 | AX23: 44958 | AY23: 72.52 | AZ23: =AVERAGE(AY3:AY23) -> 67.620952 | CC23: 43131 | CD23: 35.75
B24: 44959 | C24: 72.15 | D24: =AVERAGE(C4:C24) -> 68.065714 | Z24: 43132 | AA24: 36.78 | AX24: 44959 | AY24: 72.15 | AZ24: =AY24*$AZ$1+AZ23*(1-$AZ$1) -> 68.05229 | CC24: 43132 | CD24: 36.78
B25: 44960 | C25: 73.4 | D25: =AVERAGE(C5:C25) -> 68.49619 | Z25: 43133 | AA25: 35.9 | AX25: 44960 | AY25: 73.4 | AZ25: =AY25*$AZ$1+AZ24*(1-$AZ$1) -> 68.561596 | CC25: 43133 | CD25: 35.9
B26: 44963 | C26: 72.14 | D26: =AVERAGE(C6:C26) -> 68.93381 | Z26: 43136 | AA26: 34 | AX26: 44963 | AY26: 72.14 | AZ26: =AY26*$AZ$1+AZ25*(1-$AZ$1) -> 68.902396 | CC26: 43136 | CD26: 34
B27: 44964 | C27: 73.35 | D27: =AVERAGE(C7:C27) -> 69.363333 | Z27: 43137 | AA27: 33.59 | AX27: 44964 | AY27: 73.35 | AZ27: =AY27*$AZ$1+AZ26*(1-$AZ$1) -> 69.325978 | CC27: 43137 | CD27: 33.59
B28: 44965 | C28: 73.89 | D28: =AVERAGE(C8:C28) -> 69.771429 | Z28: 43138 | AA28: 33.75 | AX28: 44965 | AY28: 73.89 | AZ28: =AY28*$AZ$1+AZ27*(1-$AZ$1) -> 69.760646 | CC28: 43138 | CD28: 33.75
B29: 44966 | C29: 68.4 | D29: =AVERAGE(C9:C29) -> 69.860952 | Z29: 43139 | AA29: 32.03 | AX29: 44966 | AY29: 68.4 | AZ29: =AY29*$AZ$1+AZ28*(1-$AZ$1) -> 69.631061 | CC29: 43139 | CD29: 32.03
B30: 44967 | C30: 70.66 | D30: =AVERAGE(C10:C30) -> 70.002857 | Z30: 43140 | AA30: 32.33 | AX30: 44967 | AY30: 70.66 | AZ30: =AY30*$AZ$1+AZ29*(1-$AZ$1) -> 69.729055 | CC30: 43140 | CD30: 32.33
B31: 44970 | C31: 71.07 | D31: =AVERAGE(C11:C31) -> 70.128095 | Z31: 43143 | AA31: 33.02 | AX31: 44970 | AY31: 71.07 | AZ31: =AY31*$AZ$1+AZ30*(1-$AZ$1) -> 69.856764 | CC31: 43143 | CD31: 33.02
B32: 44971 | C32: 71.66 | D32: =AVERAGE(C12:C32) -> 70.220952 | Z32: 43144 | AA32: 33.57 | AX32: 44971 | AY32: 71.66 | AZ32: =AY32*$AZ$1+AZ31*(1-$AZ$1) -> 70.028501 | CC32: 43144 | CD32: 33.57
B33: 44972 | C33: 72.43 | D33: =AVERAGE(C13:C33) -> 70.38 | Z33: 43145 | AA33: 34.28 | AX33: 44972 | AY33: 72.43 | AZ33: =AY33*$AZ$1+AZ32*(1-$AZ$1) -> 70.257215 | CC33: 43145 | CD33: 34.28
B34: 44973 | C34: 72.09 | D34: =AVERAGE(C14:C34) -> 70.573333 | Z34: 43146 | AA34: 34.52 | AX34: 44973 | AY34: 72.09 | AZ34: =AY34*$AZ$1+AZ33*(1-$AZ$1) -> 70.431766 | CC34: 43146 | CD34: 34.52
B35: 44974 | C35: 71.44 | D35: =AVERAGE(C15:C35) -> 70.842857 | Z35: 43147 | AA35: 34.01 | AX35: 44974 | AY35: 71.44 | AZ35: =AY35*$AZ$1+AZ34*(1-$AZ$1) -> 70.527788 | CC35: 43147 | CD35: 34.01
... B42: 44986 | C42: 71.94 | D42: =AVERAGE(C22:C42) -> 71.473333 | Z42: 43159 | AA42: 32.8 | AX42: 44986 | AY42: 71.94 | AZ42: =AY42*$AZ$1+AZ41*(1-$AZ$1) -> 70.677216 | CC42: 43159 | CD42: 32.8
B43: 44987 | C43: 72.38 | D43: =AVERAGE(C23:C43) -> 71.549524 | Z43: 43160 | AA43: 31.99 | AX43: 44987 | AY43: 72.38 | AZ43: =AY43*$AZ$1+AZ42*(1-$AZ$1) -> 70.839386 | BC43: =AZ43-AVERAGE(AZ23:AZ43) -> 0.97910792 | BE43: =AZ43+BC43 -> 71.818494 | CC43: 43160 | CD43: 31.99
B44: 44988 | C44: 73.11 | D44: =AVERAGE(C24:C44) -> 71.577619 | Z44: 43161 | AA44: 32.05 | AX44: 44988 | AY44: 73.11 | AZ44: =AY44*$AZ$1+AZ43*(1-$AZ$1) -> 71.055635 | BC44: =AZ44-AVERAGE(AZ24:AZ44) -> 1.0318006 | BE44: =AZ44+BC44 -> 72.087435 | CC44: 43161 | CD44: 32.05
B45: 44991 | C45: 72.54 | D45: =AVERAGE(C25:C45) -> 71.59619 | Z45: 43164 | AA45: 32.45 | AX45: 44991 | AY45: 72.54 | AZ45: =AY45*$AZ$1+AZ44*(1-$AZ$1) -> 71.197003 | BC45: =AZ45-AVERAGE(AZ25:AZ45) -> 1.0234205 | BE45: =AZ45+BC45 -> 72.220423 | CC45: 43164 | CD45: 32.45
B46: 44992 | C46: 71.2 | D46: =AVERAGE(C26:C46) -> 71.491429 | Z46: 43165 | AA46: 32.85 | AX46: 44992 | AY46: 71.2 | AZ46: =AY46*$AZ$1+AZ45*(1-$AZ$1) -> 71.197288 | BC46: =AZ46-AVERAGE(AZ26:AZ46) -> 0.89819677 | BE46: =AZ46+BC46 -> 72.095485 | CC46: 43165 | CD46: 32.85
B47: 44993 | C47: 71.23 | D47: =AVERAGE(C27:C47) -> 71.448095 | Z47: 43166 | AA47: 32.75 | AX47: 44993 | AY47: 71.23 | AZ47: =AY47*$AZ$1+AZ46*(1-$AZ$1) -> 71.200404 | BC47: =AZ47-AVERAGE(AZ27:AZ47) -> 0.79188325 | BE47: =AZ47+BC47 -> 71.992287 | CC47: 43166 | CD47: 32.75
B48: 44994 | C48: 67.37 | D48: =AVERAGE(C28:C48) -> 71.163333 | Z48: 43167 | AA48: 33.01 | AX48: 44994 | AY48: 67.37 | AZ48: =AY48*$AZ$1+AZ47*(1-$AZ$1) -> 70.835603 | BC48: =AZ48-AVERAGE(AZ28:AZ48) -> 0.35519595 | BE48: =AZ48+BC48 -> 71.190799 | CC48: 43167 | CD48: 33.01
B49: 44995 | C49: 60.29 | D49: =AVERAGE(C29:C49) -> 70.515714 | Z49: 43168 | AA49: 33.56 | AX49: 44995 | AY49: 60.29 | AZ49: =AY49*$AZ$1+AZ48*(1-$AZ$1) -> 69.83126 | BC49: =AZ49-AVERAGE(AZ29:AZ49) -> -0.65250978 | BE49: =AZ49+BC49 -> 69.17875 | CC49: 43168 | CD49: 33.56
B50: 44998 | C50: 58.47 | D50: =AVERAGE(C30:C50) -> 70.042857 | Z50: 43171 | AA50: 33.54 | AX50: 44998 | AY50: 58.47 | AZ50: =AY50*$AZ$1+AZ49*(1-$AZ$1) -> 68.749235 | BC50: =AZ50-AVERAGE(AZ30:AZ50) -> -1.6925429 | BE50: =AZ50+BC50 -> 67.056693 | CC50: 43171 | CD50: 33.54
B51: 44999 | C51: 59.76 | D51: =AVERAGE(C31:C51) -> 69.52381 | Z51: 43172 | AA51: 33.01 | AX51: 44999 | AY51: 59.76 | AZ51: =AY51*$AZ$1+AZ50*(1-$AZ$1) -> 67.893118 | BC51: =AZ51-AVERAGE(AZ31:AZ51) -> -2.4612349 | BE51: =AZ51+BC51 -> 65.431883 | CC51: 43172 | CD51: 33.01
B52: 45000 | C52: 57.61 | D52: =AVERAGE(C32:C52) -> 68.882857 | Z52: 43173 | AA52: 32.83 | AX52: 45000 | AY52: 57.61 | AZ52: =AY52*$AZ$1+AZ51*(1-$AZ$1) -> 66.913773 | BC52: =AZ52-AVERAGE(AZ32:AZ52) -> -3.300437 | BE52: =AZ52+BC52 -> 63.613336 | CC52: 43173 | CD52: 32.83
B53: 45001 | C53: 58.75 | D53: =AVERAGE(C33:C53) -> 68.268095 | E53: =AVERAGE(C3:C53) -> 68.635098 | F53: =D53-E53 -> -0.3670028 | Z53: 43174 | AA53: 32.37 | AX53: 45001 | AY53: 58.75 | AZ53: =AY53*$AZ$1+AZ52*(1-$AZ$1) -> 66.136271 | BA53: =AVERAGE(AY3:AY53) -> 68.635098 | BC53: =AZ53-AVERAGE(AZ33:AZ53) -> -3.892595 | BE53: =AZ53+BC53 -> 62.243676 | CC53: 43174 | CD53: 32.37
...

Sheet Bollinger Bands
F1: 1.8 | G1: 1.8
B2: Dates | C2: Prices | D2: MA 20d | E2: Std dev | F2: UP Band | G2: DOWN Band | I2: %b | J2: Band amplitude
B3: 44929 | C3: 62.81
B4: 44930 | C4: 64.36
B5: 44931 | C5: 62.95
B6: 44932 | C6: 64.33
B7: 44935 | C7: 65.32
B8: 44936 | C8: 66.52
B9: 44937 | C9: 67.68
B10: 44938 | C10: 68.44
B11: 44939 | C11: 69.71
B12: 44943 | C12: 69.09
B13: 44944 | C13: 68.03
B14: 44945 | C14: 65.78
... B22: 44957 | C22: 70.78
B23: 44958 | C23: 72.52 | D23: =AVERAGE(C3:C23) -> 67.620952 | E23: =STDEV(C3:C23) -> 2.6483427 | F23: =D23+$F$1*E23 -> 72.387969 | G23: =D23-$G$1*E23 -> 62.853936 | I23: =(C23-G23)/(F23-G23) -> 1.0138484 | J23: =(F23-G23)/D23 -> 0.1409923
B24: 44959 | C24: 72.15 | D24: =AVERAGE(C4:C24) -> 68.065714 | E24: =STDEV(C4:C24) -> 2.5834794 | F24: =D24+$F$1*E24 -> 72.715977 | G24: =D24-$G$1*E24 -> 63.415451 | I24: =(C24-G24)/(F24-G24) -> 0.93914568 | J24: =(F24-G24)/D24 -> 0.13664039
B25: 44960 | C25: 73.4 | D25: =AVERAGE(C5:C25) -> 68.49619 | E25: =STDEV(C5:C25) -> 2.6862436 | F25: =D25+$F$1*E25 -> 73.331429 | G25: =D25-$G$1*E25 -> 63.660952 | I25: =(C25-G25)/(F25-G25) -> 1.0070908 | J25: =(F25-G25)/D25 -> 0.1411827
B26: 44963 | C26: 72.14 | D26: =AVERAGE(C6:C26) -> 68.93381 | E26: =STDEV(C6:C26) -> 2.4780385 | F26: =D26+$F$1*E26 -> 73.394279 | G26: =D26-$G$1*E26 -> 64.47334 | I26: =(C26-G26)/(F26-G26) -> 0.85940058 | J26: =(F26-G26)/D26 -> 0.12941311
B27: 44964 | C27: 73.35 | D27: =AVERAGE(C7:C27) -> 69.363333 | E27: =STDEV(C7:C27) -> 2.4212277 | F27: =D27+$F$1*E27 -> 73.721543 | G27: =D27-$G$1*E27 -> 65.005124 | I27: =(C27-G27)/(F27-G27) -> 0.95737434 | J27: =(F27-G27)/D27 -> 0.12566322
B28: 44965 | C28: 73.89 | D28: =AVERAGE(C8:C28) -> 69.771429 | E28: =STDEV(C8:C28) -> 2.4278762 | F28: =D28+$F$1*E28 -> 74.141606 | G28: =D28-$G$1*E28 -> 65.401251 | I28: =(C28-G28)/(F28-G28) -> 0.97121333 | J28: =(F28-G28)/D28 -> 0.12527125
B29: 44966 | C29: 68.4 | D29: =AVERAGE(C9:C29) -> 69.860952 | E29: =STDEV(C9:C29) -> 2.3348702 | F29: =D29+$F$1*E29 -> 74.063719 | G29: =D29-$G$1*E29 -> 65.658186 | I29: =(C29-G29)/(F29-G29) -> 0.32619158 | J29: =(F29-G29)/D29 -> 0.12031804
B30: 44967 | C30: 70.66 | D30: =AVERAGE(C10:C30) -> 70.002857 | E30: =STDEV(C10:C30) -> 2.2857321 | F30: =D30+$F$1*E30 -> 74.117175 | G30: =D30-$G$1*E30 -> 65.888539 | I30: =(C30-G30)/(F30-G30) -> 0.57986049 | J30: =(F30-G30)/D30 -> 0.11754714
B31: 44970 | C31: 71.07 | D31: =AVERAGE(C11:C31) -> 70.128095 | E31: =STDEV(C11:C31) -> 2.2677999 | F31: =D31+$F$1*E31 -> 74.210135 | G31: =D31-$G$1*E31 -> 66.046055 | I31: =(C31-G31)/(F31-G31) -> 0.61537183 | J31: =(F31-G31)/D31 -> 0.11641667
B32: 44971 | C32: 71.66 | D32: =AVERAGE(C12:C32) -> 70.220952 | E32: =STDEV(C12:C32) -> 2.2896417 | F32: =D32+$F$1*E32 -> 74.342307 | G32: =D32-$G$1*E32 -> 66.099597 | I32: =(C32-G32)/(F32-G32) -> 0.67458428 | J32: =(F32-G32)/D32 -> 0.11738249
B33: 44972 | C33: 72.43 | D33: =AVERAGE(C13:C33) -> 70.38 | E33: =STDEV(C13:C33) -> 2.3229163 | F33: =D33+$F$1*E33 -> 74.561249 | G33: =D33-$G$1*E33 -> 66.198751 | I33: =(C33-G33)/(F33-G33) -> 0.74514204 | J33: =(F33-G33)/D33 -> 0.11881925 | L33: A greater width of the bands corresponds to high volatility. A lower amplitude corresponds vice versa to a low volatility. If the bands are converging, the volatility is decreasing. Diverging bands mean an increasing volatility.
B34: 44973 | C34: 72.09 | D34: =AVERAGE(C14:C34) -> 70.573333 | E34: =STDEV(C14:C34) -> 2.2862138 | F34: =D34+$F$1*E34 -> 74.688518 | G34: =D34-$G$1*E34 -> 66.458149 | I34: =(C34-G34)/(F34-G34) -> 0.68427686 | J34: =(F34-G34)/D34 -> 0.11662152
B35: 44974 | C35: 71.44 | D35: =AVERAGE(C15:C35) -> 70.842857 | E35: =STDEV(C15:C35) -> 2.0097889 | F35: =D35+$F$1*E35 -> 74.460477 | G35: =D35-$G$1*E35 -> 67.225237 | I35: =(C35-G35)/(F35-G35) -> 0.58253256 | J35: =(F35-G35)/D35 -> 0.10213083 | L35: According to popular opinions, the Bollinger bands are suggesting to buy or sell when the following conditions occur:
B36: 44978 | C36: 69.35 | D36: =AVERAGE(C16:C36) -> 70.951429 | E36: =STDEV(C16:C36) -> 1.8511031 | F36: =D36+$F$1*E36 -> 74.283414 | G36: =D36-$G$1*E36 -> 67.619443 | I36: =(C36-G36)/(F36-G36) -> 0.25968856 | J36: =(F36-G36)/D36 -> 0.093923004 | L36: • when the price line exits the upper limit of the band and then falls in again, this is a short signal;
